Message from TWCC HPC admin
-----------------------
loading miniconda3 with conda 4.8.4/python 3.7
docs : https://hackmd.io/@kmo/twcc_hpc_conda
-----------------------

# conda environments:
#
                         /home/kodmas2023/miniconda3/envs/ape
                         /home/kodmas2023/miniconda3/envs/ape2
base                  *  /opt/ohpc/twcc/conda/4.8.3/miniconda3

[INFO] : Generating prompts from llama2 ...
Traceback (most recent call last):
  File "/home/kodmas2023/miniconda3/envs/ape/lib/python3.9/site-packages/huggingface_hub/utils/_errors.py", line 270, in hf_raise_for_status
    response.raise_for_status()
  File "/home/kodmas2023/miniconda3/envs/ape/lib/python3.9/site-packages/requests/models.py", line 1021, in raise_for_status
    raise HTTPError(http_error_msg, response=self)
requests.exceptions.HTTPError: 404 Client Error: Not Found for url: https://huggingface.co/Meta-Llama-3-8B/resolve/main/tokenizer_config.json

The above exception was the direct cause of the following exception:

Traceback (most recent call last):
  File "/home/kodmas2023/miniconda3/envs/ape/lib/python3.9/site-packages/transformers/utils/hub.py", line 430, in cached_file
    resolved_file = hf_hub_download(
  File "/home/kodmas2023/miniconda3/envs/ape/lib/python3.9/site-packages/huggingface_hub/utils/_validators.py", line 118, in _inner_fn
    return fn(*args, **kwargs)
  File "/home/kodmas2023/miniconda3/envs/ape/lib/python3.9/site-packages/huggingface_hub/file_download.py", line 1374, in hf_hub_download
    raise head_call_error
  File "/home/kodmas2023/miniconda3/envs/ape/lib/python3.9/site-packages/huggingface_hub/file_download.py", line 1247, in hf_hub_download
    metadata = get_hf_file_metadata(
  File "/home/kodmas2023/miniconda3/envs/ape/lib/python3.9/site-packages/huggingface_hub/utils/_validators.py", line 118, in _inner_fn
    return fn(*args, **kwargs)
  File "/home/kodmas2023/miniconda3/envs/ape/lib/python3.9/site-packages/huggingface_hub/file_download.py", line 1624, in get_hf_file_metadata
    r = _request_wrapper(
  File "/home/kodmas2023/miniconda3/envs/ape/lib/python3.9/site-packages/huggingface_hub/file_download.py", line 402, in _request_wrapper
    response = _request_wrapper(
  File "/home/kodmas2023/miniconda3/envs/ape/lib/python3.9/site-packages/huggingface_hub/file_download.py", line 426, in _request_wrapper
    hf_raise_for_status(response)
  File "/home/kodmas2023/miniconda3/envs/ape/lib/python3.9/site-packages/huggingface_hub/utils/_errors.py", line 320, in hf_raise_for_status
    raise RepositoryNotFoundError(message, response) from e
huggingface_hub.utils._errors.RepositoryNotFoundError: 404 Client Error. (Request ID: Root=1-66236c73-5a3ec8ea5b9c4bae6917f037;a81fe579-e22f-4e2c-9991-6d71d7e93351)

Repository Not Found for url: https://huggingface.co/Meta-Llama-3-8B/resolve/main/tokenizer_config.json.
Please make sure you specified the correct `repo_id` and `repo_type`.
If you are trying to access a private or gated repo, make sure you are authenticated.

The above exception was the direct cause of the following exception:

Traceback (most recent call last):
  File "/work/kodmas2023/automatic_prompt_engineer/slurm/../experiments/run_instruction_induction.py", line 127, in <module>
    fire.Fire(run)
  File "/home/kodmas2023/miniconda3/envs/ape/lib/python3.9/site-packages/fire/core.py", line 141, in Fire
    component_trace = _Fire(component, args, parsed_flag_args, context, name)
  File "/home/kodmas2023/miniconda3/envs/ape/lib/python3.9/site-packages/fire/core.py", line 475, in _Fire
    component, remaining_args = _CallAndUpdateTrace(
  File "/home/kodmas2023/miniconda3/envs/ape/lib/python3.9/site-packages/fire/core.py", line 691, in _CallAndUpdateTrace
    component = fn(*varargs, **kwargs)
  File "/work/kodmas2023/automatic_prompt_engineer/slurm/../experiments/run_instruction_induction.py", line 63, in run
    res, demo_fn = ape.find_prompts(eval_template=eval_template,
  File "/work/kodmas2023/automatic_prompt_engineer/automatic_prompt_engineer/ape.py", line 165, in find_prompts
    prompts = generate.generate_llama2_prompts(
  File "/work/kodmas2023/automatic_prompt_engineer/automatic_prompt_engineer/generate.py", line 67, in generate_llama2_prompts
    llama2_model = llm.Llama2Model(config)
  File "/work/kodmas2023/automatic_prompt_engineer/automatic_prompt_engineer/llm.py", line 54, in __init__
    self.tokenizer = AutoTokenizer.from_pretrained(model_name)
  File "/home/kodmas2023/miniconda3/envs/ape/lib/python3.9/site-packages/transformers/models/auto/tokenization_auto.py", line 718, in from_pretrained
    tokenizer_config = get_tokenizer_config(pretrained_model_name_or_path, **kwargs)
  File "/home/kodmas2023/miniconda3/envs/ape/lib/python3.9/site-packages/transformers/models/auto/tokenization_auto.py", line 550, in get_tokenizer_config
    resolved_config_file = cached_file(
  File "/home/kodmas2023/miniconda3/envs/ape/lib/python3.9/site-packages/transformers/utils/hub.py", line 451, in cached_file
    raise EnvironmentError(
OSError: Meta-Llama-3-8B is not a local folder and is not a valid model identifier listed on 'https://huggingface.co/models'
If this is a private repository, make sure to pass a token having permission to this repo either by logging in with `huggingface-cli login` or by passing `token=<your_token>`
